{"trial_id": "0021", "hyperparameters": {"space": [{"class_name": "Choice", "config": {"name": "activation", "default": "relu", "conditions": [], "values": ["relu", "tanh", "leaky_relu"], "ordered": false}}, {"class_name": "Int", "config": {"name": "first_units", "default": null, "conditions": [], "min_value": 1, "max_value": 30, "step": 5, "sampling": "linear"}}, {"class_name": "Int", "config": {"name": "num_layers", "default": null, "conditions": [], "min_value": 1, "max_value": 5, "step": 1, "sampling": "linear"}}, {"class_name": "Int", "config": {"name": "units_0", "default": null, "conditions": [], "min_value": 1, "max_value": 30, "step": 5, "sampling": "linear"}}, {"class_name": "Int", "config": {"name": "units_1", "default": null, "conditions": [], "min_value": 1, "max_value": 30, "step": 5, "sampling": "linear"}}, {"class_name": "Int", "config": {"name": "units_2", "default": null, "conditions": [], "min_value": 1, "max_value": 30, "step": 5, "sampling": "linear"}}, {"class_name": "Int", "config": {"name": "units_3", "default": null, "conditions": [], "min_value": 1, "max_value": 30, "step": 5, "sampling": "linear"}}, {"class_name": "Int", "config": {"name": "units_4", "default": null, "conditions": [], "min_value": 1, "max_value": 30, "step": 5, "sampling": "linear"}}], "values": {"activation": "tanh", "first_units": 1, "num_layers": 5, "units_0": 16, "units_1": 11, "units_2": 6, "units_3": 21, "units_4": 11, "tuner/epochs": 7, "tuner/initial_epoch": 0, "tuner/bracket": 1, "tuner/round": 0}}, "metrics": {"metrics": {}}, "score": null, "best_step": 0, "status": "FAILED", "message": "Traceback (most recent call last):\n  File \"/opt/anaconda3/lib/python3.11/site-packages/keras_tuner/src/engine/base_tuner.py\", line 274, in _try_run_and_update_trial\n    self._run_and_update_trial(trial, *fit_args, **fit_kwargs)\n  File \"/opt/anaconda3/lib/python3.11/site-packages/keras_tuner/src/engine/base_tuner.py\", line 239, in _run_and_update_trial\n    results = self.run_trial(trial, *fit_args, **fit_kwargs)\n              ^^^^^^^^^^^^^^^^^^^^^^^^^^^^^^^^^^^^^^^^^^^^^^\n  File \"/opt/anaconda3/lib/python3.11/site-packages/keras_tuner/src/tuners/hyperband.py\", line 427, in run_trial\n    return super().run_trial(trial, *fit_args, **fit_kwargs)\n           ^^^^^^^^^^^^^^^^^^^^^^^^^^^^^^^^^^^^^^^^^^^^^^^^^\n  File \"/opt/anaconda3/lib/python3.11/site-packages/keras_tuner/src/engine/tuner.py\", line 314, in run_trial\n    obj_value = self._build_and_fit_model(trial, *args, **copied_kwargs)\n                ^^^^^^^^^^^^^^^^^^^^^^^^^^^^^^^^^^^^^^^^^^^^^^^^^^^^^^^^\n  File \"/opt/anaconda3/lib/python3.11/site-packages/keras_tuner/src/engine/tuner.py\", line 233, in _build_and_fit_model\n    results = self.hypermodel.fit(hp, model, *args, **kwargs)\n              ^^^^^^^^^^^^^^^^^^^^^^^^^^^^^^^^^^^^^^^^^^^^^^^\n  File \"/opt/anaconda3/lib/python3.11/site-packages/keras_tuner/src/engine/hypermodel.py\", line 149, in fit\n    return model.fit(*args, **kwargs)\n           ^^^^^^^^^^^^^^^^^^^^^^^^^^\n  File \"/opt/anaconda3/lib/python3.11/site-packages/keras/src/utils/traceback_utils.py\", line 122, in error_handler\n    raise e.with_traceback(filtered_tb) from None\n  File \"/opt/anaconda3/lib/python3.11/site-packages/tensorflow/python/eager/execute.py\", line 59, in quick_execute\n    except TypeError as e:\ntensorflow.python.framework.errors_impl.InvalidArgumentError: Graph execution error:\n\nDetected at node adam/truediv_9 defined at (most recent call last):\n  File \"<frozen runpy>\", line 198, in _run_module_as_main\n\n  File \"<frozen runpy>\", line 88, in _run_code\n\n  File \"/opt/anaconda3/lib/python3.11/site-packages/ipykernel_launcher.py\", line 17, in <module>\n\n  File \"/opt/anaconda3/lib/python3.11/site-packages/traitlets/config/application.py\", line 992, in launch_instance\n\n  File \"/opt/anaconda3/lib/python3.11/site-packages/ipykernel/kernelapp.py\", line 701, in start\n\n  File \"/opt/anaconda3/lib/python3.11/site-packages/tornado/platform/asyncio.py\", line 195, in start\n\n  File \"/opt/anaconda3/lib/python3.11/asyncio/base_events.py\", line 607, in run_forever\n\n  File \"/opt/anaconda3/lib/python3.11/asyncio/base_events.py\", line 1922, in _run_once\n\n  File \"/opt/anaconda3/lib/python3.11/asyncio/events.py\", line 80, in _run\n\n  File \"/opt/anaconda3/lib/python3.11/site-packages/ipykernel/kernelbase.py\", line 534, in dispatch_queue\n\n  File \"/opt/anaconda3/lib/python3.11/site-packages/ipykernel/kernelbase.py\", line 523, in process_one\n\n  File \"/opt/anaconda3/lib/python3.11/site-packages/ipykernel/kernelbase.py\", line 429, in dispatch_shell\n\n  File \"/opt/anaconda3/lib/python3.11/site-packages/ipykernel/kernelbase.py\", line 767, in execute_request\n\n  File \"/opt/anaconda3/lib/python3.11/site-packages/ipykernel/ipkernel.py\", line 429, in do_execute\n\n  File \"/opt/anaconda3/lib/python3.11/site-packages/ipykernel/zmqshell.py\", line 549, in run_cell\n\n  File \"/opt/anaconda3/lib/python3.11/site-packages/IPython/core/interactiveshell.py\", line 3051, in run_cell\n\n  File \"/opt/anaconda3/lib/python3.11/site-packages/IPython/core/interactiveshell.py\", line 3106, in _run_cell\n\n  File \"/opt/anaconda3/lib/python3.11/site-packages/IPython/core/async_helpers.py\", line 129, in _pseudo_sync_runner\n\n  File \"/opt/anaconda3/lib/python3.11/site-packages/IPython/core/interactiveshell.py\", line 3311, in run_cell_async\n\n  File \"/opt/anaconda3/lib/python3.11/site-packages/IPython/core/interactiveshell.py\", line 3493, in run_ast_nodes\n\n  File \"/opt/anaconda3/lib/python3.11/site-packages/IPython/core/interactiveshell.py\", line 3553, in run_code\n\n  File \"/var/folders/76/jb4rsfs93334vqf862rsx8jh0000gn/T/ipykernel_94160/1784736566.py\", line 2, in <module>\n\n  File \"/opt/anaconda3/lib/python3.11/site-packages/keras_tuner/src/engine/base_tuner.py\", line 234, in search\n\n  File \"/opt/anaconda3/lib/python3.11/site-packages/keras_tuner/src/engine/base_tuner.py\", line 274, in _try_run_and_update_trial\n\n  File \"/opt/anaconda3/lib/python3.11/site-packages/keras_tuner/src/engine/base_tuner.py\", line 239, in _run_and_update_trial\n\n  File \"/opt/anaconda3/lib/python3.11/site-packages/keras_tuner/src/tuners/hyperband.py\", line 427, in run_trial\n\n  File \"/opt/anaconda3/lib/python3.11/site-packages/keras_tuner/src/engine/tuner.py\", line 314, in run_trial\n\n  File \"/opt/anaconda3/lib/python3.11/site-packages/keras_tuner/src/engine/tuner.py\", line 233, in _build_and_fit_model\n\n  File \"/opt/anaconda3/lib/python3.11/site-packages/keras_tuner/src/engine/hypermodel.py\", line 149, in fit\n\n  File \"/opt/anaconda3/lib/python3.11/site-packages/keras/src/utils/traceback_utils.py\", line 117, in error_handler\n\n  File \"/opt/anaconda3/lib/python3.11/site-packages/keras/src/backend/tensorflow/trainer.py\", line 318, in fit\n\n  File \"/opt/anaconda3/lib/python3.11/site-packages/keras/src/backend/tensorflow/trainer.py\", line 121, in one_step_on_iterator\n\n  File \"/opt/anaconda3/lib/python3.11/site-packages/keras/src/backend/tensorflow/trainer.py\", line 108, in one_step_on_data\n\n  File \"/opt/anaconda3/lib/python3.11/site-packages/keras/src/backend/tensorflow/trainer.py\", line 73, in train_step\n\n  File \"/opt/anaconda3/lib/python3.11/site-packages/keras/src/optimizers/base_optimizer.py\", line 282, in apply_gradients\n\n  File \"/opt/anaconda3/lib/python3.11/site-packages/keras/src/optimizers/base_optimizer.py\", line 351, in apply\n\n  File \"/opt/anaconda3/lib/python3.11/site-packages/keras/src/optimizers/base_optimizer.py\", line 405, in _backend_apply_gradients\n\n  File \"/opt/anaconda3/lib/python3.11/site-packages/keras/src/backend/tensorflow/optimizer.py\", line 119, in _backend_update_step\n\n  File \"/opt/anaconda3/lib/python3.11/site-packages/keras/src/backend/tensorflow/optimizer.py\", line 135, in _distributed_tf_update_step\n\n  File \"/opt/anaconda3/lib/python3.11/site-packages/keras/src/backend/tensorflow/optimizer.py\", line 132, in apply_grad_to_update_var\n\n  File \"/opt/anaconda3/lib/python3.11/site-packages/keras/src/optimizers/adam.py\", line 147, in update_step\n\n  File \"/opt/anaconda3/lib/python3.11/site-packages/keras/src/ops/numpy.py\", line 5510, in divide\n\n  File \"/opt/anaconda3/lib/python3.11/site-packages/keras/src/backend/tensorflow/sparse.py\", line 780, in sparse_wrapper\n\n  File \"/opt/anaconda3/lib/python3.11/site-packages/keras/src/backend/tensorflow/numpy.py\", line 2232, in divide\n\nIncompatible shapes: [0] vs. [16,11]\n\t [[{{node adam/truediv_9}}]] [Op:__inference_one_step_on_iterator_276414]\n"}